Traceback (most recent call last):
  File "/Users/juliafiedler/anaconda3/envs/SLI39/lib/python3.9/site-packages/jupyter_cache/executors/utils.py", line 58, in single_nb_execution
    executenb(
  File "/Users/juliafiedler/anaconda3/envs/SLI39/lib/python3.9/site-packages/nbclient/client.py", line 1305, in execute
    return NotebookClient(nb=nb, resources=resources, km=km, **kwargs).execute()
  File "/Users/juliafiedler/anaconda3/envs/SLI39/lib/python3.9/site-packages/jupyter_core/utils/__init__.py", line 162, in wrapped
    return loop.run_until_complete(inner)
  File "/Users/juliafiedler/anaconda3/envs/SLI39/lib/python3.9/asyncio/base_events.py", line 647, in run_until_complete
    return future.result()
  File "/Users/juliafiedler/anaconda3/envs/SLI39/lib/python3.9/site-packages/nbclient/client.py", line 705, in async_execute
    await self.async_execute_cell(
  File "/Users/juliafiedler/anaconda3/envs/SLI39/lib/python3.9/site-packages/nbclient/client.py", line 1058, in async_execute_cell
    await self._check_raise_for_error(cell, cell_index, exec_reply)
  File "/Users/juliafiedler/anaconda3/envs/SLI39/lib/python3.9/site-packages/nbclient/client.py", line 914, in _check_raise_for_error
    raise CellExecutionError.from_cell_and_msg(cell, exec_reply_content)
nbclient.exceptions.CellExecutionError: An error occurred while executing the following cell:
------------------
# make epoch_start equal to Jan 1 1983 in datetime format
epoch_start = datetime.datetime(1983, 1, 1)

# and for now, end time will be the end of 2023
epoch_end = datetime.datetime(2023, 12,31)


hourly_data = subset.sel(dict(time=slice(epoch_start, epoch_end)))
hourly_data = hourly_data.sortby('lat')
station_group = 'Hawaiian Islands'

glue("startEpochDateTime",epoch_start.strftime('%Y-%m-%d'), display=False)
glue("endEpochDateTime",epoch_end.strftime('%Y-%m-%d'), display=False)

glue("stationGroup",station_group,display=False)


------------------


[0;31m---------------------------------------------------------------------------[0m
[0;31mNameError[0m                                 Traceback (most recent call last)
Cell [0;32mIn[9], line 2[0m
[1;32m      1[0m [38;5;66;03m# make epoch_start equal to Jan 1 1983 in datetime format[39;00m
[0;32m----> 2[0m epoch_start [38;5;241m=[39m [43mdatetime[49m[38;5;241m.[39mdatetime([38;5;241m1983[39m, [38;5;241m1[39m, [38;5;241m1[39m)
[1;32m      4[0m [38;5;66;03m# and for now, end time will be the end of 2023[39;00m
[1;32m      5[0m epoch_end [38;5;241m=[39m datetime[38;5;241m.[39mdatetime([38;5;241m2023[39m, [38;5;241m12[39m,[38;5;241m31[39m)

[0;31mNameError[0m: name 'datetime' is not defined

