Traceback (most recent call last):
  File "/Users/juliafiedler/anaconda3/envs/SLI39/lib/python3.9/site-packages/jupyter_cache/executors/utils.py", line 58, in single_nb_execution
    executenb(
  File "/Users/juliafiedler/anaconda3/envs/SLI39/lib/python3.9/site-packages/nbclient/client.py", line 1305, in execute
    return NotebookClient(nb=nb, resources=resources, km=km, **kwargs).execute()
  File "/Users/juliafiedler/anaconda3/envs/SLI39/lib/python3.9/site-packages/jupyter_core/utils/__init__.py", line 165, in wrapped
    return loop.run_until_complete(inner)
  File "/Users/juliafiedler/anaconda3/envs/SLI39/lib/python3.9/asyncio/base_events.py", line 647, in run_until_complete
    return future.result()
  File "/Users/juliafiedler/anaconda3/envs/SLI39/lib/python3.9/site-packages/nbclient/client.py", line 705, in async_execute
    await self.async_execute_cell(
  File "/Users/juliafiedler/anaconda3/envs/SLI39/lib/python3.9/site-packages/nbclient/client.py", line 1058, in async_execute_cell
    await self._check_raise_for_error(cell, cell_index, exec_reply)
  File "/Users/juliafiedler/anaconda3/envs/SLI39/lib/python3.9/site-packages/nbclient/client.py", line 914, in _check_raise_for_error
    raise CellExecutionError.from_cell_and_msg(cell, exec_reply_content)
nbclient.exceptions.CellExecutionError: An error occurred while executing the following cell:
------------------
#make a pretty pdf of the table with great_tables
from great_tables import GT,html

dfGT = df.copy()
dfGT['year'] = df.index

# put the year column first
cols = dfGT.columns.tolist()
cols = cols[-1:] + cols[:-1]
dfGT = dfGT[cols]
dfGT.reset_index(drop=True, inplace=True)



# Create a GreatTable object
table = (GT(dfGT)
.fmt_number(columns=calendar.month_abbr[1:13], decimals=0)
.fmt_number(columns=['Annual'], decimals=0)
.tab_header(title = 'Days Exceeding 30 cm above MHHW', subtitle = station_name)
.data_color(domain = [0,30],
            columns=calendar.month_abbr[1:13],
            rows = list(range(len(dfGT)-1)),
            palette=["white", "lightblue"])
.data_color(domain = [0,30],
            columns=calendar.month_abbr[1:13],
            rows = [-1],
            palette=["white", "purple"])
)

# save table as png
tableName = station_name + '_flood_days_intra_annual.png'
savePath = os.path.join(output_dir, tableName)
table.save(savePath)

# Load Image
imgTable = Image(filename=savePath)

# Glue the image with a name
glue("imgTable", imgTable, display=False)


------------------


[0;31m---------------------------------------------------------------------------[0m
[0;31mNameError[0m                                 Traceback (most recent call last)
Cell [0;32mIn[4], line 36[0m
[1;32m     33[0m table[38;5;241m.[39msave(savePath)
[1;32m     35[0m [38;5;66;03m# Load Image[39;00m
[0;32m---> 36[0m imgTable [38;5;241m=[39m [43mImage[49m(filename[38;5;241m=[39msavePath)
[1;32m     38[0m [38;5;66;03m# Glue the image with a name[39;00m
[1;32m     39[0m glue([38;5;124m"[39m[38;5;124mimgTable[39m[38;5;124m"[39m, imgTable, display[38;5;241m=[39m[38;5;28;01mFalse[39;00m)

[0;31mNameError[0m: name 'Image' is not defined

