Traceback (most recent call last):
  File "/opt/anaconda3/envs/SLI39/lib/python3.9/site-packages/jupyter_cache/executors/utils.py", line 58, in single_nb_execution
    executenb(
  File "/opt/anaconda3/envs/SLI39/lib/python3.9/site-packages/nbclient/client.py", line 1314, in execute
    return NotebookClient(nb=nb, resources=resources, km=km, **kwargs).execute()
  File "/opt/anaconda3/envs/SLI39/lib/python3.9/site-packages/jupyter_core/utils/__init__.py", line 165, in wrapped
    return loop.run_until_complete(inner)
  File "/opt/anaconda3/envs/SLI39/lib/python3.9/asyncio/base_events.py", line 647, in run_until_complete
    return future.result()
  File "/opt/anaconda3/envs/SLI39/lib/python3.9/site-packages/nbclient/client.py", line 709, in async_execute
    await self.async_execute_cell(
  File "/opt/anaconda3/envs/SLI39/lib/python3.9/site-packages/nbclient/client.py", line 1062, in async_execute_cell
    await self._check_raise_for_error(cell, cell_index, exec_reply)
  File "/opt/anaconda3/envs/SLI39/lib/python3.9/site-packages/nbclient/client.py", line 918, in _check_raise_for_error
    raise CellExecutionError.from_cell_and_msg(cell, exec_reply_content)
nbclient.exceptions.CellExecutionError: An error occurred while executing the following cell:
------------------
# Load the data

import glob        
# Get a list of all .nc files in the data/hawaii directory
files = glob.glob('/Users/juliafiedler/Documents/SL_Indicators/data/hawaii/h*.nc')

# Open the datasets
datasets = [xr.open_dataset(file) for file in files]

#merge in batches of 2 to avoid memory issues
batch_size = 2
merged_datasets = []

for i in range(0, len(datasets), batch_size):
    batch = datasets[i:i+batch_size]
    merged_batch = xr.merge(batch)
    merged_datasets.append(merged_batch)

#merge the merged datasets
rsl = xr.merge(merged_datasets)

# convert byte strings to normal strings
rsl['station_name'] = rsl['station_name'].astype(str)
rsl['station_country'] = rsl['station_country'].astype(str)
rsl['ssc_id'] = rsl['ssc_id'].astype(str)

rsl
------------------


[0;31m---------------------------------------------------------------------------[0m
[0;31mKeyError[0m                                  Traceback (most recent call last)
[0;32m/opt/anaconda3/envs/SLI39/lib/python3.9/site-packages/xarray/core/dataset.py[0m in [0;36m?[0;34m(self, name)[0m
[1;32m   1446[0m             [0mvariable[0m [0;34m=[0m [0mself[0m[0;34m.[0m[0m_variables[0m[0;34m[[0m[0mname[0m[0;34m][0m[0;34m[0m[0;34m[0m[0m
[1;32m   1447[0m         [0;32mexcept[0m [0mKeyError[0m[0;34m:[0m[0;34m[0m[0;34m[0m[0m
[0;32m-> 1448[0;31m             [0m_[0m[0;34m,[0m [0mname[0m[0;34m,[0m [0mvariable[0m [0;34m=[0m [0m_get_virtual_variable[0m[0;34m([0m[0mself[0m[0;34m.[0m[0m_variables[0m[0;34m,[0m [0mname[0m[0;34m,[0m [0mself[0m[0;34m.[0m[0msizes[0m[0;34m)[0m[0;34m[0m[0;34m[0m[0m
[0m[1;32m   1449[0m [0;34m[0m[0m

[0;31mKeyError[0m: 'station_name'

During handling of the above exception, another exception occurred:

[0;31mKeyError[0m                                  Traceback (most recent call last)
[0;32m/opt/anaconda3/envs/SLI39/lib/python3.9/site-packages/xarray/core/dataset.py[0m in [0;36m?[0;34m(self, key)[0m
[1;32m   1545[0m                 [0;32mreturn[0m [0mself[0m[0;34m.[0m[0m_construct_dataarray[0m[0;34m([0m[0mkey[0m[0;34m)[0m[0;34m[0m[0;34m[0m[0m
[1;32m   1546[0m             [0;32mexcept[0m [0mKeyError[0m [0;32mas[0m [0me[0m[0;34m:[0m[0;34m[0m[0;34m[0m[0m
[0;32m-> 1547[0;31m                 raise KeyError(
[0m[1;32m   1548[0m                     [0;34mf"No variable named {key!r}. Variables on the dataset include {shorten_list_repr(list(self.variables.keys()), max_items=10)}"[0m[0;34m[0m[0;34m[0m[0m

[0;32m/opt/anaconda3/envs/SLI39/lib/python3.9/site-packages/xarray/core/dataset.py[0m in [0;36m?[0;34m(self, name)[0m
[1;32m   1446[0m             [0mvariable[0m [0;34m=[0m [0mself[0m[0;34m.[0m[0m_variables[0m[0;34m[[0m[0mname[0m[0;34m][0m[0;34m[0m[0;34m[0m[0m
[1;32m   1447[0m         [0;32mexcept[0m [0mKeyError[0m[0;34m:[0m[0;34m[0m[0;34m[0m[0m
[0;32m-> 1448[0;31m             [0m_[0m[0;34m,[0m [0mname[0m[0;34m,[0m [0mvariable[0m [0;34m=[0m [0m_get_virtual_variable[0m[0;34m([0m[0mself[0m[0;34m.[0m[0m_variables[0m[0;34m,[0m [0mname[0m[0;34m,[0m [0mself[0m[0;34m.[0m[0msizes[0m[0;34m)[0m[0;34m[0m[0;34m[0m[0m
[0m[1;32m   1449[0m [0;34m[0m[0m

[0;32m/opt/anaconda3/envs/SLI39/lib/python3.9/site-packages/xarray/core/dataset.py[0m in [0;36m?[0;34m(variables, key, dim_sizes)[0m
[1;32m    205[0m     [0msplit_key[0m [0;34m=[0m [0mkey[0m[0;34m.[0m[0msplit[0m[0;34m([0m[0;34m"."[0m[0;34m,[0m [0;36m1[0m[0;34m)[0m[0;34m[0m[0;34m[0m[0m
[1;32m    206[0m     [0;32mif[0m [0mlen[0m[0;34m([0m[0msplit_key[0m[0;34m)[0m [0;34m!=[0m [0;36m2[0m[0;34m:[0m[0;34m[0m[0;34m[0m[0m
[0;32m--> 207[0;31m         [0;32mraise[0m [0mKeyError[0m[0;34m([0m[0mkey[0m[0;34m)[0m[0;34m[0m[0;34m[0m[0m
[0m[1;32m    208[0m [0;34m[0m[0m

[0;31mKeyError[0m: 'station_name'

The above exception was the direct cause of the following exception:

[0;31mKeyError[0m                                  Traceback (most recent call last)
[0;32m/var/folders/qp/nn19rcjs5bdcdvxmff5bd3pr0000gn/T/ipykernel_9183/1774169243.py[0m in [0;36m?[0;34m()[0m
[0;32m---> 23[0;31m [0;31m# Load the data[0m[0;34m[0m[0;34m[0m[0m
[0m[1;32m     24[0m [0;34m[0m[0m
[1;32m     25[0m [0;32mimport[0m [0mglob[0m[0;34m[0m[0;34m[0m[0m
[1;32m     26[0m [0;31m# Get a list of all .nc files in the data/hawaii directory[0m[0;34m[0m[0;34m[0m[0m

[0;32m/opt/anaconda3/envs/SLI39/lib/python3.9/site-packages/xarray/core/dataset.py[0m in [0;36m?[0;34m(self, key)[0m
[1;32m   1543[0m         [0;32mif[0m [0mutils[0m[0;34m.[0m[0mhashable[0m[0;34m([0m[0mkey[0m[0;34m)[0m[0;34m:[0m[0;34m[0m[0;34m[0m[0m
[1;32m   1544[0m             [0;32mtry[0m[0;34m:[0m[0;34m[0m[0;34m[0m[0m
[1;32m   1545[0m                 [0;32mreturn[0m [0mself[0m[0;34m.[0m[0m_construct_dataarray[0m[0;34m([0m[0mkey[0m[0;34m)[0m[0;34m[0m[0;34m[0m[0m
[1;32m   1546[0m             [0;32mexcept[0m [0mKeyError[0m [0;32mas[0m [0me[0m[0;34m:[0m[0;34m[0m[0;34m[0m[0m
[0;32m-> 1547[0;31m                 raise KeyError(
[0m[1;32m   1548[0m                     [0;34mf"No variable named {key!r}. Variables on the dataset include {shorten_list_repr(list(self.variables.keys()), max_items=10)}"[0m[0;34m[0m[0;34m[0m[0m
[1;32m   1549[0m                 ) from e
[1;32m   1550[0m [0;34m[0m[0m

[0;31mKeyError[0m: "No variable named 'station_name'. Variables on the dataset include []"

