Traceback (most recent call last):
  File "/Users/juliafiedler/anaconda3/envs/SLI39/lib/python3.9/site-packages/jupyter_cache/executors/utils.py", line 58, in single_nb_execution
    executenb(
  File "/Users/juliafiedler/anaconda3/envs/SLI39/lib/python3.9/site-packages/nbclient/client.py", line 1305, in execute
    return NotebookClient(nb=nb, resources=resources, km=km, **kwargs).execute()
  File "/Users/juliafiedler/anaconda3/envs/SLI39/lib/python3.9/site-packages/jupyter_core/utils/__init__.py", line 162, in wrapped
    return loop.run_until_complete(inner)
  File "/Users/juliafiedler/anaconda3/envs/SLI39/lib/python3.9/asyncio/base_events.py", line 647, in run_until_complete
    return future.result()
  File "/Users/juliafiedler/anaconda3/envs/SLI39/lib/python3.9/site-packages/nbclient/client.py", line 705, in async_execute
    await self.async_execute_cell(
  File "/Users/juliafiedler/anaconda3/envs/SLI39/lib/python3.9/site-packages/nbclient/client.py", line 1058, in async_execute_cell
    await self._check_raise_for_error(cell, cell_index, exec_reply)
  File "/Users/juliafiedler/anaconda3/envs/SLI39/lib/python3.9/site-packages/nbclient/client.py", line 914, in _check_raise_for_error
    raise CellExecutionError.from_cell_and_msg(cell, exec_reply_content)
nbclient.exceptions.CellExecutionError: An error occurred while executing the following cell:
------------------
url = "https://uhslc.soest.hawaii.edu/data/netcdf/fast/hourly/" 
uhslc_ids = list(stationdict.values())

for uhslc_id in uhslc_ids:
    fname = f'h{uhslc_id}.nc' # h for hourly, d for daily

    path = os.path.join(data_dir, 'tide_gauge_nc',fname)

    if not os.path.exists(path):
        urlretrieve(os.path.join(url, fname), path) 
        print(f'Downloading {fname} from {url} to {path}')
------------------


[0;31m---------------------------------------------------------------------------[0m
[0;31mFileNotFoundError[0m                         Traceback (most recent call last)
Cell [0;32mIn[3], line 10[0m
[1;32m      7[0m path [38;5;241m=[39m os[38;5;241m.[39mpath[38;5;241m.[39mjoin(data_dir, [38;5;124m'[39m[38;5;124mtide_gauge_nc[39m[38;5;124m'[39m,fname)
[1;32m      9[0m [38;5;28;01mif[39;00m [38;5;129;01mnot[39;00m os[38;5;241m.[39mpath[38;5;241m.[39mexists(path):
[0;32m---> 10[0m     [43murlretrieve[49m[43m([49m[43mos[49m[38;5;241;43m.[39;49m[43mpath[49m[38;5;241;43m.[39;49m[43mjoin[49m[43m([49m[43murl[49m[43m,[49m[43m [49m[43mfname[49m[43m)[49m[43m,[49m[43m [49m[43mpath[49m[43m)[49m 
[1;32m     11[0m     [38;5;28mprint[39m([38;5;124mf[39m[38;5;124m'[39m[38;5;124mDownloading [39m[38;5;132;01m{[39;00mfname[38;5;132;01m}[39;00m[38;5;124m from [39m[38;5;132;01m{[39;00murl[38;5;132;01m}[39;00m[38;5;124m to [39m[38;5;132;01m{[39;00mpath[38;5;132;01m}[39;00m[38;5;124m'[39m)

File [0;32m~/anaconda3/envs/SLI39/lib/python3.9/urllib/request.py:249[0m, in [0;36murlretrieve[0;34m(url, filename, reporthook, data)[0m
[1;32m    247[0m [38;5;66;03m# Handle temporary file setup.[39;00m
[1;32m    248[0m [38;5;28;01mif[39;00m filename:
[0;32m--> 249[0m     tfp [38;5;241m=[39m [38;5;28;43mopen[39;49m[43m([49m[43mfilename[49m[43m,[49m[43m [49m[38;5;124;43m'[39;49m[38;5;124;43mwb[39;49m[38;5;124;43m'[39;49m[43m)[49m
[1;32m    250[0m [38;5;28;01melse[39;00m:
[1;32m    251[0m     tfp [38;5;241m=[39m tempfile[38;5;241m.[39mNamedTemporaryFile(delete[38;5;241m=[39m[38;5;28;01mFalse[39;00m)

[0;31mFileNotFoundError[0m: [Errno 2] No such file or directory: 'SL_Hawaii/data/tide_gauge_nc/h060.nc'

