Traceback (most recent call last):
  File "C:\Users\julia\anaconda3\envs\SLI39\lib\site-packages\jupyter_cache\executors\utils.py", line 58, in single_nb_execution
    executenb(
  File "C:\Users\julia\anaconda3\envs\SLI39\lib\site-packages\nbclient\client.py", line 1314, in execute
    return NotebookClient(nb=nb, resources=resources, km=km, **kwargs).execute()
  File "C:\Users\julia\anaconda3\envs\SLI39\lib\site-packages\jupyter_core\utils\__init__.py", line 165, in wrapped
    return loop.run_until_complete(inner)
  File "C:\Users\julia\anaconda3\envs\SLI39\lib\asyncio\base_events.py", line 647, in run_until_complete
    return future.result()
  File "C:\Users\julia\anaconda3\envs\SLI39\lib\site-packages\nbclient\client.py", line 709, in async_execute
    await self.async_execute_cell(
  File "C:\Users\julia\anaconda3\envs\SLI39\lib\site-packages\nbclient\client.py", line 1062, in async_execute_cell
    await self._check_raise_for_error(cell, cell_index, exec_reply)
  File "C:\Users\julia\anaconda3\envs\SLI39\lib\site-packages\nbclient\client.py", line 918, in _check_raise_for_error
    raise CellExecutionError.from_cell_and_msg(cell, exec_reply_content)
nbclient.exceptions.CellExecutionError: An error occurred while executing the following cell:
------------------
w_s_plot = adjust_w_for_plotting(icromo,w_s_plot,w_s)
------------------


[1;31m---------------------------------------------------------------------------[0m
[1;31mTypeError[0m                                 Traceback (most recent call last)
Cell [1;32mIn[11], line 1[0m
[1;32m----> 1[0m w_s_plot [38;5;241m=[39m [43madjust_w_for_plotting[49m[43m([49m[43micromo[49m[43m,[49m[43mw_s_plot[49m[43m,[49m[43mw_s[49m[43m)[49m

[1;31mTypeError[0m: adjust_w_for_plotting() takes 2 positional arguments but 3 were given

