Traceback (most recent call last):
  File "/opt/anaconda3/envs/SLI39/lib/python3.9/site-packages/jupyter_cache/executors/utils.py", line 58, in single_nb_execution
    executenb(
  File "/opt/anaconda3/envs/SLI39/lib/python3.9/site-packages/nbclient/client.py", line 1314, in execute
    return NotebookClient(nb=nb, resources=resources, km=km, **kwargs).execute()
  File "/opt/anaconda3/envs/SLI39/lib/python3.9/site-packages/jupyter_core/utils/__init__.py", line 165, in wrapped
    return loop.run_until_complete(inner)
  File "/opt/anaconda3/envs/SLI39/lib/python3.9/asyncio/base_events.py", line 647, in run_until_complete
    return future.result()
  File "/opt/anaconda3/envs/SLI39/lib/python3.9/site-packages/nbclient/client.py", line 709, in async_execute
    await self.async_execute_cell(
  File "/opt/anaconda3/envs/SLI39/lib/python3.9/site-packages/nbclient/client.py", line 1062, in async_execute_cell
    await self._check_raise_for_error(cell, cell_index, exec_reply)
  File "/opt/anaconda3/envs/SLI39/lib/python3.9/site-packages/nbclient/client.py", line 918, in _check_raise_for_error
    raise CellExecutionError.from_cell_and_msg(cell, exec_reply_content)
nbclient.exceptions.CellExecutionError: An error occurred while executing the following cell:
------------------
avg_daily = daily_mean.sel('time'=slice(1983,2001)).groupby('dayofyear').mean(dim='time') #CHECK IF THIS IS RIGHT, SOMETHING IS WRONG
avg_high = daily_max.groupby('dayofyear').mean(dim='time')
avg_low = daily_min.groupby('dayofyear').mean(dim='time')

record_low = daily_min.groupby('dayofyear').min(dim='time')
record_high = daily_max.groupby('dayofyear').max(dim='time')

------------------


[0;36m  Cell [0;32mIn[6], line 1[0;36m[0m
[0;31m    avg_daily = daily_mean.sel('time'=slice(1983,2001)).groupby('dayofyear').mean(dim='time') #CHECK IF THIS IS RIGHT, SOMETHING IS WRONG[0m
[0m                               ^[0m
[0;31mSyntaxError[0m[0;31m:[0m expression cannot contain assignment, perhaps you meant "=="?


