Traceback (most recent call last):
  File "/Users/juliafiedler/anaconda3/envs/SLI39/lib/python3.9/site-packages/jupyter_cache/executors/utils.py", line 58, in single_nb_execution
    executenb(
  File "/Users/juliafiedler/anaconda3/envs/SLI39/lib/python3.9/site-packages/nbclient/client.py", line 1305, in execute
    return NotebookClient(nb=nb, resources=resources, km=km, **kwargs).execute()
  File "/Users/juliafiedler/anaconda3/envs/SLI39/lib/python3.9/site-packages/jupyter_core/utils/__init__.py", line 162, in wrapped
    return loop.run_until_complete(inner)
  File "/Users/juliafiedler/anaconda3/envs/SLI39/lib/python3.9/asyncio/base_events.py", line 647, in run_until_complete
    return future.result()
  File "/Users/juliafiedler/anaconda3/envs/SLI39/lib/python3.9/site-packages/nbclient/client.py", line 705, in async_execute
    await self.async_execute_cell(
  File "/Users/juliafiedler/anaconda3/envs/SLI39/lib/python3.9/site-packages/nbclient/client.py", line 1058, in async_execute_cell
    await self._check_raise_for_error(cell, cell_index, exec_reply)
  File "/Users/juliafiedler/anaconda3/envs/SLI39/lib/python3.9/site-packages/nbclient/client.py", line 914, in _check_raise_for_error
    raise CellExecutionError.from_cell_and_msg(cell, exec_reply_content)
nbclient.exceptions.CellExecutionError: An error occurred while executing the following cell:
------------------
g = rsl_daily.sea_level.plot(x='time', col='record_id', col_wrap=3, sharey=False, sharex=True, figsize=(15, 10))

# Use g.axs to iterate over the axes in the FacetGrid
for ax, rid in zip(g.axs.flat, rsl_daily.record_id):
    # Accessing the station_name coordinate for the current record_id directly
    station_name = rsl_daily.station_name.sel(record_id=rid).item()
    ax.set_title(station_name)
    ax.set_ylim(-0.5, 0.7)

plt.show()
------------------


[0;31m---------------------------------------------------------------------------[0m
[0;31mAttributeError[0m                            Traceback (most recent call last)
Cell [0;32mIn[4], line 1[0m
[0;32m----> 1[0m g [38;5;241m=[39m [43mrsl_daily[49m[38;5;241;43m.[39;49m[43msea_level[49m[38;5;241m.[39mplot(x[38;5;241m=[39m[38;5;124m'[39m[38;5;124mtime[39m[38;5;124m'[39m, col[38;5;241m=[39m[38;5;124m'[39m[38;5;124mrecord_id[39m[38;5;124m'[39m, col_wrap[38;5;241m=[39m[38;5;241m3[39m, sharey[38;5;241m=[39m[38;5;28;01mFalse[39;00m, sharex[38;5;241m=[39m[38;5;28;01mTrue[39;00m, figsize[38;5;241m=[39m([38;5;241m15[39m, [38;5;241m10[39m))
[1;32m      3[0m [38;5;66;03m# Use g.axs to iterate over the axes in the FacetGrid[39;00m
[1;32m      4[0m [38;5;28;01mfor[39;00m ax, rid [38;5;129;01min[39;00m [38;5;28mzip[39m(g[38;5;241m.[39maxs[38;5;241m.[39mflat, rsl_daily[38;5;241m.[39mrecord_id):
[1;32m      5[0m     [38;5;66;03m# Accessing the station_name coordinate for the current record_id directly[39;00m

File [0;32m~/anaconda3/envs/SLI39/lib/python3.9/site-packages/xarray/core/common.py:278[0m, in [0;36mAttrAccessMixin.__getattr__[0;34m(self, name)[0m
[1;32m    276[0m         [38;5;28;01mwith[39;00m suppress([38;5;167;01mKeyError[39;00m):
[1;32m    277[0m             [38;5;28;01mreturn[39;00m source[name]
[0;32m--> 278[0m [38;5;28;01mraise[39;00m [38;5;167;01mAttributeError[39;00m(
[1;32m    279[0m     [38;5;124mf[39m[38;5;124m"[39m[38;5;132;01m{[39;00m[38;5;28mtype[39m([38;5;28mself[39m)[38;5;241m.[39m[38;5;18m__name__[39m[38;5;132;01m!r}[39;00m[38;5;124m object has no attribute [39m[38;5;132;01m{[39;00mname[38;5;132;01m!r}[39;00m[38;5;124m"[39m
[1;32m    280[0m )

[0;31mAttributeError[0m: 'Dataset' object has no attribute 'sea_level'

